Workbook

Sheet Listas
A1: Dimensão | B1: Disciplinas | C1: Impacto | D1: Gravidade | E1: Abrangência | F1: Recorrente | G1: Tensões | R1: Disciplinas DE | S1: Disciplinas PARA | T1: Detalhe
A2: Diagnóstico e Benchmarking | B2: Maturidade atual | C2: Previsibilidade de Prazo e Entrega | D2: 1 - Baixo (Pontual / Localizado) | E2: Local | F2: Sim | G2: Estrutural | R2: Governança e Gestão de Portfólio | S2: Gestão de Portfólio e Ciclo de Vida | T2: FEL, Ciclo de Vida, Maturidade de Engenharia, Planejamento Físico, Econômico, Financeiro, Gestão de Riscos
A3: Estrutura Organizacional e Governança | B3: Benchmark interno | C3: Eficiência e Controle de Capital | D3: 2 - Moderado (Afeta eficiência) | E3: Multi-Projeto | F3: Não | G3: Processual | R3: Planejamento e Controle Integrado | S3: Gestão de Portfólio e Ciclo de Vida | T3: FEL, Ciclo de Vida, Maturidade de Engenharia, Planejamento Físico, Econômico, Financeiro, Gestão de Riscos
A4: Metodologias e Engenharia de Valor | B4: Benchmark externo | C4: Qualidade da Tomada de Decisão de Investimentos | D4: 3 - Relevante (Afeta previsibilidade) | E4: Organizacional | G4: Informacional | R4: Estimativas e Gestão de Custos | S4: Gestão de Portfólio e Ciclo de Vida | T4: FEL, Ciclo de Vida, Maturidade de Engenharia, Planejamento Físico, Econômico, Financeiro, Gestão de Riscos
A5: Gestão Contratual e Contingências | B5: Boas práticas e referências | C5: Efetividade da Governança de CAPEX | D5: 4 - Alto (Impacto estrutural) | E5: Sistêmico | G5: Técnica | R5: Gestão Contratual e Riscos | S5: Administração Contratual | T5: Administração Contratual, Medições, Pleitos
A6: Gestão de Portfólio e PMO | B6: Lacunas e oportunidades | C6: Eficiência Operacional da Execução | D6: 5 - Crítico (Risco sistêmico) | G6: Financeira | R6: Gestão Contratual e Riscos | S6: Gestão de Portfólio e Ciclo de Vida | T6: FEL, Ciclo de Vida, Maturidade de Engenharia, Planejamento Físico, Econômico, Financeiro, Gestão de Riscos
A7: Tecnologia, Dados e Sistemas | B7: Modelo organizacional | C7: Exposição a Riscos de Investimento | G7: Incentivos e Cultura | R7: Governança Técnica e Engenharia | S7: Engenharia de Valor
A8: Maturidade Técnica e Engenharia | B8: Papéis e responsabilidades | C8: Qualidade Técnica e Maturidade de Engenharia | G8: Capacidade | R8: Suprimentos e Estratégia de Contratação
B9: Alçadas e decisões | C9: Performance Contratual e Cadeia de Fornecimento | R9: Tecnologia, Dados e Sistemas
B10: Comitês e fóruns | C10: Confiabilidade da Informação e Suporte à Decisão | R10: Organização, Cultura e Modelo Operacional
B11: Capacidade e competências | T11: Comitê de CapEx
B12: Ritos e Fluxo de Governança | T12: Suprimentos
B13: Metodologia de gestão CAPEX | T13: Gestão de Conhecimento
B14: Padrões e templates | T14: Papéis, Responsabilidades e Alçadas
B15: Gestão do conhecimento | E15: 1️⃣ Local / Pontual
B16: Engenharia de valor | E16: Um projeto específico
B17: Critérios de avaliação e priorização técnica | E17: Uma equipe específica
B18: Administração contratual | E18: Um contrato específico
B19: Pleitos e aditivos | E19: Sem impacto estruturante no portfólio.
B20: Conformidade contratual | E20: 2️⃣ Multi-Projeto
B21: Política de contingências | E21: Mais de um projeto
B22: Exposição financeira | E22: Uma plataforma
B23: Integração com áreas corporativas | E23: Uma carteira específica
B24: Governança de portfólio | E24: Impacta eficiência, mas não toda a empresa.
B25: Priorização e pipeline | E25: 3️⃣ Organizacional
B26: Ciclo de vida e gates | E26: Afeta:
... B37: Rastreabilidade da informação | E37: Impacto transversal e estratégico.

Sheet Estrutura TOR
A1: # TOR | B1: TOR | C1: Dimensões | D1: Disciplinas
A2: 3.1 | B2: Avaliação e Benchmarking | C2: Diagnóstico e Benchmarking | D2: Maturidade atual; Benchmark interno; Benchmark externo; Boas práticas e referências; Lacunas e oportunidades
A3: 3.2 | B3: Estrutura matricial, papéis, processos e responsabilidades | C3: Estrutura e Governança do CAPEX | D3: Modelo organizacional; Papéis e responsabilidades; Alçadas e decisões; Comitês e fóruns; Capacidade e competências
A4: 3.3 | B4: Padronização de metodologias e gestão do conhecimento | C4: Metodologias e Engenharia de Valor | D4: Metodologia de gestão CAPEX; Padrões e templates ;Gestão do conhecimento; Engenharia de valor ;Critérios de avaliação e priorização técnica
A5: 3.4 | B5: Governança da Administração Contratual | C5: Gestão Contratual e Contingências | D5: Administração contratual; Pleitos e aditivos; Conformidade contratual; Política de contingências; Exposição financeira e uso de contingência
A6: 3.5 | B6: Engenharia de Valor em nível corporativo e de projetos | C6: Metodologias e Engenharia de Valor | D6: Metodologia de gestão CAPEX; Padrões e templates ;Gestão do conhecimento; Engenharia de valor ;Critérios de avaliação e priorização técnica
A7: 3.6 | B7: Governança de contingências de CAPEX | C7: Gestão Contratual e Contingências | D7: Administração contratual; Pleitos e aditivos; Conformidade contratual; Política de contingências; Exposição financeira e uso de contingência
A8: 3.7 | B8: Gestão do portfólio de investimentos | C8: Gestão de Portfólio e PMO | D8: Governança de portfólio; Priorização e pipeline; Ciclo de vida e gates; PMO corporativo e plataformas; Monitoramento físico-financeiro; Indicadores e reports executivos
A9: 3.8 | B9: Escritório de Projetos (corporativo e por plataforma) | C9: Gestão de Portfólio e PMO | D9: Governança de portfólio; Priorização e pipeline; Ciclo de vida e gates; PMO corporativo e plataformas; Monitoramento físico-financeiro; Indicadores e reports executivos
A10: 3.9 | B10: Modelo de governança e integração de sistemas e dados | C10: Tecnologia, Dados e Sistemas | D10: Arquitetura de sistemas; Integração entre sistemas; Modelo e governança de dados; Reports e dashboards; Rastreabilidade da informação
A11: 3.10 | B11: Comitê de CAPEX e Governança Decisória | C11: Estrutura e Governança do CAPEX | D11: Modelo organizacional; Papéis e responsabilidades; Alçadas e decisões; Comitês e fóruns; Capacidade e competências
A12: 3.11 | B12: Competências, cargos e capacidade do Núcleo | C12: Estrutura e Governança do CAPEX | D12: Modelo organizacional; Papéis e responsabilidades; Alçadas e decisões; Comitês e fóruns; Capacidade e competências

Sheet Estrutura TOR2
A1: # TOR | B1: TOR | C1: Dimensões | D1: Disciplinas | E1: Detalhamento
A2: 3.1 | B2: Avaliação e Benchmarking | C2: Diagnóstico e Benchmarking | D2: Maturidade atual | E2: Avaliação do nível atual de governança e gestão de CAPEX
A3: 3.1 | B3: Avaliação e Benchmarking | C3: Diagnóstico e Benchmarking | D3: Benchmark interno | E3: Comparação entre plataformas (ex.: Trilhos × Rodovias)
A4: 3.1 | B4: Avaliação e Benchmarking | C4: Diagnóstico e Benchmarking | D4: Benchmark externo | E4: Referências de mercado e boas práticas
A5: 3.1 | B5: Avaliação e Benchmarking | C5: Diagnóstico e Benchmarking | D5: Boas práticas e referências | E5: Identificação de modelos de governança e gestão aplicáveis
A6: 3.1 | B6: Avaliação e Benchmarking | C6: Diagnóstico e Benchmarking | D6: Lacunas e oportunidades | E6: Principais gaps estruturais identificados
A7: 3.2 | B7: Estrutura matricial, papéis, processos e responsabilidades | C7: Estrutura Organizacional e Governança do CAPEX | D7: Modelo organizacional | E7: Estrutura do Núcleo, posicionamento organizacional e interfaces
A8: 3.2 | B8: Estrutura matricial, papéis, processos e responsabilidades | C8: Estrutura Organizacional e Governança do CAPEX | D8: Papéis e responsabilidades | E8: Distribuição de responsabilidades entre áreas e funções
A9: 3.2 | B9: Estrutura matricial, papéis, processos e responsabilidades | C9: Estrutura Organizacional e Governança do CAPEX | D9: Alçadas e decisões | E9: Matriz decisória, critérios por valor, prazo e criticidade
A10: 3.2 | B10: Estrutura matricial, papéis, processos e responsabilidades | C10: Estrutura Organizacional e Governança do CAPEX | D10: Comitês e fóruns | E10: Estrutura e funcionamento dos fóruns decisórios e Comitê de CAPEX
A11: 3.2 | B11: Estrutura matricial, papéis, processos e responsabilidades | C11: Estrutura Organizacional e Governança do CAPEX | D11: Capacidade e competências | E11: Dimensionamento do Núcleo, perfis profissionais e competências
A12: 3.2 | B12: Estrutura matricial, papéis, processos e responsabilidades | C12: Estrutura Organizacional e Governança do CAPEX | D12: Ritos e Fluxo de Governança | E12: Funcionamento dos fóruns, rituais e fluxos decisórios para avaliação e aprovação de investimentos de CAPEX.
... A68: 3.11 | B68: Competências, cargos e capacidade do Núcleo | C68: Estrutura Organizacional e Governança do CAPEX | D68: Ritos e Fluxo de Governança | E68: Funcionamento dos fóruns, rituais e fluxos decisórios para avaliação e aprovação de investimentos de CAPEX.

Sheet Estrutura
A1: Estrutura completa do diagnóstico
A2: Nível 1 — Evidência Literal
A3: Trecho literal da entrevista
A4: "Cada área aprova projetos de um jeito diferente."
A6: Nível 2 — Problema estrutural
A7: Interpretação analítica da evidência
A8: Ausência de padronização na governança decisória de investimentos
A10: Nível 3 — Dimensão
A11: Framework atual
A12: Estrutura Organizacional e Governança do CAPEX
A14: Nível 4 — Disciplina
A15: Onde o problema ocorre
... A23: Quantas entrevistas citaram o mesmo problema

Sheet Taxonomias
A1: Dimensão | B1: Definição
A2: Estrutura Organizacional e Governança do CAPEX | B2: Definição do modelo organizacional do Núcleo de CAPEX, incluindo papéis, responsabilidades, alçadas decisórias, fóruns de governança e fluxos de decisão que suportam a gestão dos investimentos.
A3: Metodologias e Engenharia de Valor | B3: Estrutura metodológica utilizada para gestão de projetos de CAPEX, incluindo padronização de processos, templates, gestão do conhecimento e aplicação de práticas de engenharia de valor para otimização técnica e econômica dos projetos.
A4: Gestão Contratual e Contingências | B4: Estrutura de governança e gestão do ciclo contratual do CAPEX, incluindo administração de contratos, gestão de pleitos e aditivos, conformidade contratual, política de contingências e monitoramento de exposição financeira.
A5: Gestão de Portfólio e PMO | B5: Estrutura de governança responsável pela seleção, priorização, acompanhamento e controle do portfólio de investimentos, incluindo atuação do PMO, monitoramento físico-financeiro, indicadores executivos e gestão de riscos do portfólio.
A6: Tecnologia, Dados e Sistemas | B6: Estrutura de sistemas, governança de dados e ferramentas analíticas utilizadas para suportar a gestão do CAPEX, garantindo integração de informações, confiabilidade de dados, rastreabilidade e suporte à tomada de decisão.
A8: Disciplina | B8: Definição
A9: Maturidade atual | B9: Avaliação do nível atual de governança e gestão do CAPEX na organização.
A10: Benchmark interno | B10: Comparação de práticas entre plataformas ou áreas da organização.
A11: Benchmark externo | B11: Comparação com práticas de mercado e referências de gestão de CAPEX.
A12: Boas práticas e referências | B12: Identificação de práticas consolidadas e modelos de referência utilizados na gestão de CAPEX.
A13: Lacunas e oportunidades | B13: Identificação de lacunas estruturais e oportunidades de evolução na gestão do CAPEX.
... A55: Confiabilidade da Informação e Suporte à Decisão | B55: Impactos na qualidade, rastreabilidade e disponibilidade de dados e sistemas para gestão e tomada de decisão.

Sheet  Lista de Entrevistas
A1: entrevista_id | B1: Nome | C1: Cargo | D1: Diretoria | E1: Plataforma | F1: Área | G1: Nível | H1: Data | I1: Entrevista
A2: 1 | B2: Paulo Cesar Martins Amaral | C2: =VLOOKUP($B2,'Lista de Entrevistas_BD'!$D$2:$M$121,4,FALSE) -> Consultor Contratos Implantação | D2: =VLOOKUP($B2,'Lista de Entrevistas_BD'!$D$2:$M$121,5,FALSE) -> VP Trilhos | E2: =VLOOKUP($B2,'Lista de Entrevistas_BD'!$D$2:$M$121,7,FALSE) -> Trilhos | F2: Administração Contratual | G2: Operacional | H2: =VLOOKUP($B2,'Lista de Entrevistas_BD'!$D$2:$M$121,8,FALSE) -> 46073.375 | I2: Coleta de Dados
A3: 2 | B3: Paulo Henrique de Almeida Aredes | C3: =VLOOKUP($B3,'Lista de Entrevistas_BD'!$D$2:$M$121,4,FALSE) -> Consultor Contratos Implantação (L4) | D3: =VLOOKUP($B3,'Lista de Entrevistas_BD'!$D$2:$M$121,5,FALSE) -> VP Trilhos | E3: =VLOOKUP($B3,'Lista de Entrevistas_BD'!$D$2:$M$121,7,FALSE) -> Trilhos | F3: Contratos e Riscos | G3: Operacional | H3: =VLOOKUP($B3,'Lista de Entrevistas_BD'!$D$2:$M$121,8,FALSE) -> 46073.438 | I3: Coleta de Dados
A4: 3 | B4: Rodrigo Correa de Souza | C4: =VLOOKUP($B4,'Lista de Entrevistas_BD'!$D$2:$M$121,4,FALSE) -> Consultor Engenharia | D4: =VLOOKUP($B4,'Lista de Entrevistas_BD'!$D$2:$M$121,5,FALSE) -> VP Trilhos | E4: =VLOOKUP($B4,'Lista de Entrevistas_BD'!$D$2:$M$121,7,FALSE) -> Trilhos | F4: Engenharia de Implantação / Qualidade | G4: Operacional | H4: =VLOOKUP($B4,'Lista de Entrevistas_BD'!$D$2:$M$121,8,FALSE) -> 46073.562 | I4: Coleta de Dados
A5: 4 | B5: Rodrigo Mitsuo Kise | C5: =VLOOKUP($B5,'Lista de Entrevistas_BD'!$D$2:$M$121,4,FALSE) -> Gerente Executivo Empreedimentos e PMO - Projetos Técnicos (L4) | D5: =VLOOKUP($B5,'Lista de Entrevistas_BD'!$D$2:$M$121,5,FALSE) -> VP Trilhos | E5: =VLOOKUP($B5,'Lista de Entrevistas_BD'!$D$2:$M$121,7,FALSE) -> Trilhos | F5: Gestão de Capex / Projetos | G5: Tático | H5: =VLOOKUP($B5,'Lista de Entrevistas_BD'!$D$2:$M$121,8,FALSE) -> 46073.625 | I5: Coleta de Dados
A6: 5 | B6: Emilio Simon Povoa | C6: =VLOOKUP($B6,'Lista de Entrevistas_BD'!$D$2:$M$121,4,FALSE) -> Gerente Executivo Gerenciamento de Riscos | D6: =VLOOKUP($B6,'Lista de Entrevistas_BD'!$D$2:$M$121,5,FALSE) -> VP Trilhos | E6: =VLOOKUP($B6,'Lista de Entrevistas_BD'!$D$2:$M$121,7,FALSE) -> Trilhos | F6: Engenharia de Implantação | G6: Tático | H6: =VLOOKUP($B6,'Lista de Entrevistas_BD'!$D$2:$M$121,8,FALSE) -> 46073.708 | I6: Coleta de Dados
A7: 6 | B7: Vanilza de Souza Pandolfo | C7: =VLOOKUP($B7,'Lista de Entrevistas_BD'!$D$2:$M$121,4,FALSE) -> Consultora Riscos Engenharia | D7: =VLOOKUP($B7,'Lista de Entrevistas_BD'!$D$2:$M$121,5,FALSE) -> VP Trilhos | E7: =VLOOKUP($B7,'Lista de Entrevistas_BD'!$D$2:$M$121,7,FALSE) -> Trilhos | F7: Gestão de Riscos de Projetos | G7: Operacional | H7: =VLOOKUP($B7,'Lista de Entrevistas_BD'!$D$2:$M$121,8,FALSE) -> 46076.438 | I7: Coleta de Dados
A8: 7 | B8: William Nascimento Marins | C8: =VLOOKUP($B8,'Lista de Entrevistas_BD'!$D$2:$M$121,4,FALSE) -> Gerente de PMO | D8: =VLOOKUP($B8,'Lista de Entrevistas_BD'!$D$2:$M$121,5,FALSE) -> VP Trilhos | E8: =VLOOKUP($B8,'Lista de Entrevistas_BD'!$D$2:$M$121,7,FALSE) -> Trilhos | F8: PMO / Demais Empreendimentos | G8: Tático | H8: =VLOOKUP($B8,'Lista de Entrevistas_BD'!$D$2:$M$121,8,FALSE) -> 46076.583 | I8: Coleta de Dados
A9: 8 | B9: Michel Simoes Araujo | C9: =VLOOKUP($B9,'Lista de Entrevistas_BD'!$D$2:$M$121,4,FALSE) -> Gerente Executivo Acompanhamento de Projetos | D9: =VLOOKUP($B9,'Lista de Entrevistas_BD'!$D$2:$M$121,5,FALSE) -> VP Trilhos | E9: =VLOOKUP($B9,'Lista de Entrevistas_BD'!$D$2:$M$121,7,FALSE) -> Trilhos | F9: Capex / Engenharia | G9: Tático | H9: =VLOOKUP($B9,'Lista de Entrevistas_BD'!$D$2:$M$121,8,FALSE) -> 46076.646 | I9: Coleta de Dados
A10: 9 | B10: Jean Carlos Bonin da Silva | C10: =VLOOKUP($B10,'Lista de Entrevistas_BD'!$D$2:$M$121,4,FALSE) -> Coordenador PMO | D10: =VLOOKUP($B10,'Lista de Entrevistas_BD'!$D$2:$M$121,5,FALSE) -> VP Trilhos | E10: =VLOOKUP($B10,'Lista de Entrevistas_BD'!$D$2:$M$121,7,FALSE) -> Trilhos | F10: Planejamento / PMO | G10: Operacional | H10: =VLOOKUP($B10,'Lista de Entrevistas_BD'!$D$2:$M$121,8,FALSE) -> 46077.458 | I10: Coleta de Dados
A11: 10 | B11: Rebeka Yang Wang | C11: =VLOOKUP($B11,'Lista de Entrevistas_BD'!$D$2:$M$121,4,FALSE) -> Coordenadora PMO | D11: =VLOOKUP($B11,'Lista de Entrevistas_BD'!$D$2:$M$121,5,FALSE) -> VP Trilhos | E11: =VLOOKUP($B11,'Lista de Entrevistas_BD'!$D$2:$M$121,7,FALSE) -> Trilhos | F11: PMO Engenharia Trilhos | G11: Operacional | H11: =VLOOKUP($B11,'Lista de Entrevistas_BD'!$D$2:$M$121,8,FALSE) -> 46077.562 | I11: Coleta de Dados
A12: 11 | B12: Ricardo Alexandre Benicio | C12: =VLOOKUP($B12,'Lista de Entrevistas_BD'!$D$2:$M$121,4,FALSE) -> Diretor Engenharia de Manutenção | D12: =VLOOKUP($B12,'Lista de Entrevistas_BD'!$D$2:$M$121,5,FALSE) -> VP Trilhos | E12: =VLOOKUP($B12,'Lista de Entrevistas_BD'!$D$2:$M$121,7,FALSE) -> Trilhos | F12: Engenharia de Operação e Manutenção / Expansão Linha 4 | G12: Estratégico | H12: =VLOOKUP($B12,'Lista de Entrevistas_BD'!$D$2:$M$121,8,FALSE) -> 46077.688 | I12: Coleta de Dados
A13: 12 | B13: Elmo Serejo Pithon Copello | C13: =VLOOKUP($B13,'Lista de Entrevistas_BD'!$D$2:$M$121,4,FALSE) -> Gerente Engenharia Empreedimentos | D13: =VLOOKUP($B13,'Lista de Entrevistas_BD'!$D$2:$M$121,5,FALSE) -> VP Trilhos | E13: =VLOOKUP($B13,'Lista de Entrevistas_BD'!$D$2:$M$121,7,FALSE) -> Trilhos | F13: Projetos – Demais Empreendimentos | G13: Tático | H13: =VLOOKUP($B13,'Lista de Entrevistas_BD'!$D$2:$M$121,8,FALSE) -> 46078.646 | I13: Coleta de Dados
... A18: 17 | B18: Danieli Patricia Ribeiro | C18: =VLOOKUP($B18,'Lista de Entrevistas_BD'!$D$2:$M$121,4,FALSE) -> Assessora Projetos Corporativos | D18: =VLOOKUP($B18,'Lista de Entrevistas_BD'!$D$2:$M$121,5,FALSE) -> VP Financeiro e Relações Investidores | E18: =VLOOKUP($B18,'Lista de Entrevistas_BD'!$D$2:$M$121,7,FALSE) -> Corporativo | F18: Assessora Projetos Corporativos | G18: Estratégico | H18: =VLOOKUP($B18,'Lista de Entrevistas_BD'!$D$2:$M$121,8,FALSE) -> 46084.625 | I18: Coleta de Dados
A19: 18 | B19: Guilherme Tellis | C19: =VLOOKUP($B19,'Lista de Entrevistas_BD'!$D$2:$M$121,4,FALSE) -> Especialista de PMO | D19: =VLOOKUP($B19,'Lista de Entrevistas_BD'!$D$2:$M$121,5,FALSE) -> VP Trilhos | E19: =VLOOKUP($B19,'Lista de Entrevistas_BD'!$D$2:$M$121,7,FALSE) -> Trilhos | H19: =VLOOKUP($B19,'Lista de Entrevistas_BD'!$D$2:$M$121,8,FALSE) -> 46080.583 | I19: Coleta de Dados
A20: 19 | B20: Juliana Magalhaes Vasconcelos Salomao | C20: =VLOOKUP($B20,'Lista de Entrevistas_BD'!$D$2:$M$121,4,FALSE) -> Gerente Gestão Fornecedores e Sustentação | D20: =VLOOKUP($B20,'Lista de Entrevistas_BD'!$D$2:$M$121,5,FALSE) -> VP Financeiro e Relações Investidores | E20: =VLOOKUP($B20,'Lista de Entrevistas_BD'!$D$2:$M$121,7,FALSE) -> Corporativo | F20: Sustentação | G20: Estratégico | H20: =VLOOKUP($B20,'Lista de Entrevistas_BD'!$D$2:$M$121,8,FALSE) -> 46084.562 | I20: Coleta de Dados
A21: 20 | B21: Gustavo Henrique Lucas Jaquie | C21: =VLOOKUP($B21,'Lista de Entrevistas_BD'!$D$2:$M$121,4,FALSE) -> Gerente Executivo Engenharia Projetos e Centro Expertise | D21: =VLOOKUP($B21,'Lista de Entrevistas_BD'!$D$2:$M$121,5,FALSE) -> VP Trilhos | E21: =VLOOKUP($B21,'Lista de Entrevistas_BD'!$D$2:$M$121,7,FALSE) -> Trilhos | H21: =VLOOKUP($B21,'Lista de Entrevistas_BD'!$D$2:$M$121,8,FALSE) -> 46072.583 | I21: Coleta de Dados
A22: 21 | B22: Afranio Nogueira Magalhaes | C22: =VLOOKUP($B22,'Lista de Entrevistas_BD'!$D$2:$M$121,4,FALSE) -> Gerente Executivo Engenharia e Obras | D22: =VLOOKUP($B22,'Lista de Entrevistas_BD'!$D$2:$M$121,5,FALSE) -> VP Rodovias | E22: =VLOOKUP($B22,'Lista de Entrevistas_BD'!$D$2:$M$121,7,FALSE) -> Rodovias | H22: =VLOOKUP($B22,'Lista de Entrevistas_BD'!$D$2:$M$121,8,FALSE) -> 46100.458 | I22: Coleta de Dados
A23: 22 | B23: Alexandre Fontes Pereira | C23: =VLOOKUP($B23,'Lista de Entrevistas_BD'!$D$2:$M$121,4,FALSE) -> Gerente Executivo PMO, Qualidade e Riscos | D23: =VLOOKUP($B23,'Lista de Entrevistas_BD'!$D$2:$M$121,5,FALSE) -> VP Rodovias | E23: =VLOOKUP($B23,'Lista de Entrevistas_BD'!$D$2:$M$121,7,FALSE) -> Rodovias | H23: =VLOOKUP($B23,'Lista de Entrevistas_BD'!$D$2:$M$121,8,FALSE) -> 46097.583 | I23: Coleta de Dados
A24: 23 | B24: Ana Laura Marocolo Marigo | C24: =VLOOKUP($B24,'Lista de Entrevistas_BD'!$D$2:$M$121,4,FALSE) -> Coordenadora PMO | D24: =VLOOKUP($B24,'Lista de Entrevistas_BD'!$D$2:$M$121,5,FALSE) -> VP Rodovias | E24: =VLOOKUP($B24,'Lista de Entrevistas_BD'!$D$2:$M$121,7,FALSE) -> Rodovias | H24: =VLOOKUP($B24,'Lista de Entrevistas_BD'!$D$2:$M$121,8,FALSE) -> 46099.375 | I24: Coleta de Dados
A25: 24 | B25: Anderson Aparecido Zanetti | C25: =VLOOKUP($B25,'Lista de Entrevistas_BD'!$D$2:$M$121,4,FALSE) -> Consultor PMO | D25: =VLOOKUP($B25,'Lista de Entrevistas_BD'!$D$2:$M$121,5,FALSE) -> VP Rodovias | E25: =VLOOKUP($B25,'Lista de Entrevistas_BD'!$D$2:$M$121,7,FALSE) -> Rodovias | H25: =VLOOKUP($B25,'Lista de Entrevistas_BD'!$D$2:$M$121,8,FALSE) -> 46098.417 | I25: Coleta de Dados
A26: 25 | B26: Cesar Sampaio de Castro | C26: =VLOOKUP($B26,'Lista de Entrevistas_BD'!$D$2:$M$121,4,FALSE) -> Gerente Gestão Portfólio e Valor | D26: =VLOOKUP($B26,'Lista de Entrevistas_BD'!$D$2:$M$121,5,FALSE) -> VP Inovação, Tecnologia e Riscos | E26: =VLOOKUP($B26,'Lista de Entrevistas_BD'!$D$2:$M$121,7,FALSE) -> Corporativo | H26: =VLOOKUP($B26,'Lista de Entrevistas_BD'!$D$2:$M$121,8,FALSE) -> 46099.625 | I26: Coleta de Dados
A27: 26 | B27: Heloisa Helena de Oliveira Tormin Chaer | C27: =VLOOKUP($B27,'Lista de Entrevistas_BD'!$D$2:$M$121,4,FALSE) -> Gerente Executiva Planejamento e Governança | D27: =VLOOKUP($B27,'Lista de Entrevistas_BD'!$D$2:$M$121,5,FALSE) -> VP Inovação, Tecnologia e Riscos | E27: =VLOOKUP($B27,'Lista de Entrevistas_BD'!$D$2:$M$121,7,FALSE) -> Corporativo | H27: =VLOOKUP($B27,'Lista de Entrevistas_BD'!$D$2:$M$121,8,FALSE) -> 46097.688 | I27: Coleta de Dados
A28: 27 | B28: Jaime Marlon Silva | C28: =VLOOKUP($B28,'Lista de Entrevistas_BD'!$D$2:$M$121,4,FALSE) -> Gerente Executivo Soluções Engenharia e Logística | D28: =VLOOKUP($B28,'Lista de Entrevistas_BD'!$D$2:$M$121,5,FALSE) -> VP Inovação, Tecnologia e Riscos | E28: =VLOOKUP($B28,'Lista de Entrevistas_BD'!$D$2:$M$121,7,FALSE) -> Corporativo | H28: =VLOOKUP($B28,'Lista de Entrevistas_BD'!$D$2:$M$121,8,FALSE) -> 46097.583 | I28: Coleta de Dados
A29: 28 | B29: Jorge Rangel Maia | C29: =VLOOKUP($B29,'Lista de Entrevistas_BD'!$D$2:$M$121,4,FALSE) -> Gerente Executivo Suprimentos Mobilidade e Aero | D29: =VLOOKUP($B29,'Lista de Entrevistas_BD'!$D$2:$M$121,5,FALSE) -> VP Financeiro e Relações Investidores | E29: =VLOOKUP($B29,'Lista de Entrevistas_BD'!$D$2:$M$121,7,FALSE) -> Corporativo | H29: =VLOOKUP($B29,'Lista de Entrevistas_BD'!$D$2:$M$121,8,FALSE) -> 46098.583 | I29: Coleta de Dados
A30: 29 | B30: Jorge Manuel Goncalves Pereira | C30: =VLOOKUP($B30,'Lista de Entrevistas_BD'!$D$2:$M$121,4,FALSE) -> Gerente Executivo Estratégia de Operações | D30: =VLOOKUP($B30,'Lista de Entrevistas_BD'!$D$2:$M$121,5,FALSE) -> VP Rodovias | E30: =VLOOKUP($B30,'Lista de Entrevistas_BD'!$D$2:$M$121,7,FALSE) -> Rodovias | H30: =VLOOKUP($B30,'Lista de Entrevistas_BD'!$D$2:$M$121,8,FALSE) -> 46099.583 | I30: Coleta de Dados
A31: 30 | B31: Juliana Ming Martini Naressi | C31: =VLOOKUP($B31,'Lista de Entrevistas_BD'!$D$2:$M$121,4,FALSE) -> Coordenador Compras Sustentáveis | D31: =VLOOKUP($B31,'Lista de Entrevistas_BD'!$D$2:$M$121,5,FALSE) -> VP Financeiro e Relações Investidores | E31: =VLOOKUP($B31,'Lista de Entrevistas_BD'!$D$2:$M$121,7,FALSE) -> Corporativo | H31: =VLOOKUP($B31,'Lista de Entrevistas_BD'!$D$2:$M$121,8,FALSE) -> 46100.583 | I31: Coleta de Dados
A32: 31 | B32: Karina Baungartner | C32: =VLOOKUP($B32,'Lista de Entrevistas_BD'!$D$2:$M$121,4,FALSE) -> Gerente PMO Rodovias | D32: =VLOOKUP($B32,'Lista de Entrevistas_BD'!$D$2:$M$121,5,FALSE) -> VP Rodovias | E32: =VLOOKUP($B32,'Lista de Entrevistas_BD'!$D$2:$M$121,7,FALSE) -> Rodovias | H32: =VLOOKUP($B32,'Lista de Entrevistas_BD'!$D$2:$M$121,8,FALSE) -> 46098.396 | I32: Coleta de Dados
... A65: 64 | B65: Flavia Godoy de Carvalho E Silva | C65: =VLOOKUP($B65,'Lista de Entrevistas_BD'!$D$2:$M$121,4,FALSE) -> Diretora de Relação Investidores | D65: =VLOOKUP($B65,'Lista de Entrevistas_BD'!$D$2:$M$121,5,FALSE) -> VP Financeiro e Relações Investidores | E65: =VLOOKUP($B65,'Lista de Entrevistas_BD'!$D$2:$M$121,7,FALSE) -> Corporativo | H65: =VLOOKUP($B65,'Lista de Entrevistas_BD'!$D$2:$M$121,8,FALSE) -> 46112.583 | I65: Coleta de Dados
A66: 65 | B66: Jean Carlos Bonin da Silva - A | C66: Coordenador PMO | D66: VP Trilhos | E66: Trilhos | F66: Planejamento / PMO | G66: Operacional | H66: 46107 | I66: Aprofundamento
A67: 66 | B67: Lucas Giraldi Rapchan Aguilar - A | C67: Gerente PMO Rodovias | D67: VP Rodovias | E67: Rodovias | H67: 46104 | I67: Aprofundamento
A68: 67 | B68: Guilherme Tellis - A | C68: Especialista de PMO | D68: VP Trilhos | E68: Trilhos | H68: 46085 | I68: Aprofundamento
A69: 68 | B69: Tiago Terra Esteves - A | C69: =VLOOKUP($B69,'Lista de Entrevistas_BD'!$D$2:$M$121,4,FALSE) -> #N/A | D69: =VLOOKUP($B69,'Lista de Entrevistas_BD'!$D$2:$M$121,5,FALSE) -> #N/A | E69: Trilhos | H69: 46106 | I69: Aprofundamento
A70: 69 | B70: Vinicius Vancellote - A | C70: Especialista de PMO | D70: VP Trilhos | E70: Trilhos | F70: PMO - Demais Empreendimentos | H70: 46112 | I70: Aprofundamento

Sheet Analise Individual
A1: entrevista_id | B1: Entrevistado | C1: Nível | D1: Plataforma | E1: Diretoria | F1: Gerência Executiva | G1: Evidência Literal | H1: Problema Estrutural | I1: Dimensão | J1: Disciplina | K1: Impacto | L1: Abrangência | M1: Recorrente
A2: 16 | B2: Adriana Martins dos Santos | D2: Trilhos | G2: “Suprimentos atende sob demanda. Mas como a gente faz assim, que suprimentos realmente viva o dia a dia do negócio, não necessariamente ando dentro do negócio, não é isso não.” | H2: Contratações sem planejamento e escopo maturado | I2: Planejamento e Baseline | J2: Suprimentos e Estratégia de Contratação | K2: Contratos e Cadeia de Fornecimento | L2: Multi-Projeto | M2: Sim
A3: 16 | B3: Adriana Martins dos Santos | D3: Trilhos | G3: “Suprimentos atende sob demanda. Mas como a gente faz assim, que suprimentos realmente viva o dia a dia do negócio, não necessariamente ando dentro do negócio, não é isso não.” | H3: Contratações sem planejamento e escopo maturado | I3: Planejamento e Baseline | J3: Suprimentos e Estratégia de Contratação | K3: Prazo e Confiabilidade do Cronograma | L3: Multi-Projeto | M3: Sim
A4: 16 | B4: Adriana Martins dos Santos | D4: Trilhos | G4: “Suprimentos atende sob demanda. Mas como a gente faz assim, que suprimentos realmente viva o dia a dia do negócio, não necessariamente ando dentro do negócio, não é isso não.” | H4: Contratações sem planejamento e escopo maturado | I4: Planejamento e Baseline | J4: Suprimentos e Estratégia de Contratação | K4: Custos e Contingências | L4: Multi-Projeto | M4: Sim
A5: 16 | B5: Adriana Martins dos Santos | D5: Trilhos | G5: “Eu não transfiro gestão contratual de nenhum contrato de Capex para a operação ou para manutenção.” | H5: Governança de custos e contingências insuficiente | I5: Custos e contingências | J5: Estimativas e Gestão de Custos | K5: Custos e Contingências | L5: Organizacional | M5: Sim
A6: 16 | B6: Adriana Martins dos Santos | D6: Trilhos | G6: “Eu não transfiro gestão contratual de nenhum contrato de Capex para a operação ou para manutenção.” | H6: Governança de custos e contingências insuficiente | I6: Custos e contingências | J6: Estimativas e Gestão de Custos | K6: Governança e Performance do Portfólio | L6: Organizacional | M6: Sim
A7: 16 | B7: Adriana Martins dos Santos | D7: Trilhos | G7: “Eu não transfiro gestão contratual de nenhum contrato de Capex para a operação ou para manutenção.” | H7: Governança de custos e contingências insuficiente | I7: Custos e contingências | J7: Estimativas e Gestão de Custos | K7: Riscos e Incertezas | L7: Organizacional | M7: Sim
A8: 16 | B8: Adriana Martins dos Santos | D8: Trilhos | G8: “Hoje não existe uma integração sistêmica... é um sofrimento que a gente pelo menos acompanha para conseguir as informações.” | H8: Coordenação interáreas insuficiente e decisões ad hoc | I8: Integração Organizacional | J8: Organização, Cultura e Modelo Operacional | K8: Integração Organizacional | L8: Organizacional | M8: Sim
A9: 16 | B9: Adriana Martins dos Santos | D9: Trilhos | G9: “Hoje não existe uma integração sistêmica... é um sofrimento que a gente pelo menos acompanha para conseguir as informações.” | H9: Coordenação interáreas insuficiente e decisões ad hoc | I9: Integração Organizacional | J9: Organização, Cultura e Modelo Operacional | K9: Eficiência Operacional | L9: Organizacional | M9: Sim
A10: 16 | B10: Adriana Martins dos Santos | D10: Trilhos | G10: “Hoje não existe uma integração sistêmica... é um sofrimento que a gente pelo menos acompanha para conseguir as informações.” | H10: Coordenação interáreas insuficiente e decisões ad hoc | I10: Integração Organizacional | J10: Organização, Cultura e Modelo Operacional | K10: Governança e Performance do Portfólio | L10: Organizacional | M10: Sim
A11: 16 | B11: Adriana Martins dos Santos | D11: Trilhos | G11: “Eu não sou surpreendida, AI, eu não sabia, AI tem um aditivo. Então a gente tem processo de gestão de mudança.” | H11: Gestão contratual reativa e com pleitos | I11: Gestão Contratual e Pleitos | J11: Gestão Contratual e Riscos | K11: Contratos e Cadeia de Fornecimento | L11: Multi-Projeto | M11: Sim
A12: 16 | B12: Adriana Martins dos Santos | D12: Trilhos | G12: “Eu não sou surpreendida, AI, eu não sabia, AI tem um aditivo. Então a gente tem processo de gestão de mudança.” | H12: Gestão contratual reativa e com pleitos | I12: Gestão Contratual e Pleitos | J12: Gestão Contratual e Riscos | K12: Custos e Contingências | L12: Multi-Projeto | M12: Sim
A13: 16 | B13: Adriana Martins dos Santos | D13: Trilhos | G13: “Eu não sou surpreendida, AI, eu não sabia, AI tem um aditivo. Então a gente tem processo de gestão de mudança.” | H13: Gestão contratual reativa e com pleitos | I13: Gestão Contratual e Pleitos | J13: Gestão Contratual e Riscos | K13: Prazo e Confiabilidade do Cronograma | L13: Multi-Projeto | M13: Sim
... A427: 7 | B427: William Nascimento Marins | D427: Trilhos | G427: “Não tem uma receita de bolo... até a atividade mãe tem, está nos manuais... o detalhamento depende de experiência.” | H427: Coordenação interáreas insuficiente e decisões ad hoc | I427: Integração Organizacional | J427: Organização, Cultura e Modelo Operacional | K427: Governança e Performance do Portfólio | L427: Organizacional | M427: Sim

Sheet Evidências_Estruturadas
A1: entrevista_id | B1: Plataforma | C1: Diretoria | D1: Gerência Executiva | E1: Disciplina | F1: Evidência Literal | G1: Problema | H1: Impacto | I1: Abrangência | J1: Recorrente
A2: 15 | B2: =VLOOKUP($A2,' Lista de Entrevistas'!$A$1:$I$222,5,FALSE) -> Corporativo | C2: =VLOOKUP($A2,' Lista de Entrevistas'!$A$1:$I$222,4,FALSE) -> VP Financeiro e Relações Investidores | E2: Governança e Gestão de Portfólio | G2: Ausência de padronização no nível de maturidade da Engenharia para contratações de fornecedores | H2: Aumento de Custos
A3: 15 | B3: =VLOOKUP($A3,' Lista de Entrevistas'!$A$1:$I$222,5,FALSE) -> Corporativo | C3: =VLOOKUP($A3,' Lista de Entrevistas'!$A$1:$I$222,4,FALSE) -> VP Financeiro e Relações Investidores | E3: Governança e Gestão de Portfólio | G3: Ausência de padronização no nível de maturidade da Engenharia para contratações de fornecedores | H3: Retrabalho Suprimentos
A4: 15 | B4: =VLOOKUP($A4,' Lista de Entrevistas'!$A$1:$I$222,5,FALSE) -> Corporativo | C4: =VLOOKUP($A4,' Lista de Entrevistas'!$A$1:$I$222,4,FALSE) -> VP Financeiro e Relações Investidores | E4: Governança e Gestão de Portfólio | G4: Ausência de padronização no nível de maturidade da Engenharia para contratações de fornecedores | H4: Retrabalho Engenharia
A5: 15 | B5: =VLOOKUP($A5,' Lista de Entrevistas'!$A$1:$I$222,5,FALSE) -> Corporativo | C5: =VLOOKUP($A5,' Lista de Entrevistas'!$A$1:$I$222,4,FALSE) -> VP Financeiro e Relações Investidores | E5: Governança e Gestão de Portfólio | G5: Ausência de padronização no nível de maturidade da Engenharia para contratações de fornecedores | H5: Impacto de Prazo
A6: 15 | B6: =VLOOKUP($A6,' Lista de Entrevistas'!$A$1:$I$222,5,FALSE) -> Corporativo | C6: =VLOOKUP($A6,' Lista de Entrevistas'!$A$1:$I$222,4,FALSE) -> VP Financeiro e Relações Investidores | E6: Planejamento e Controle Integrado | G6: Falta de visibilidade no planejamento de projetos | H6: Impacto de Prazo
A7: 15 | B7: =VLOOKUP($A7,' Lista de Entrevistas'!$A$1:$I$222,5,FALSE) -> Corporativo | C7: =VLOOKUP($A7,' Lista de Entrevistas'!$A$1:$I$222,4,FALSE) -> VP Financeiro e Relações Investidores | E7: Planejamento e Controle Integrado | G7: Falta de visibilidade no planejamento de projetos | H7: Impacto de Custo
A8: 15 | B8: =VLOOKUP($A8,' Lista de Entrevistas'!$A$1:$I$222,5,FALSE) -> Corporativo | C8: =VLOOKUP($A8,' Lista de Entrevistas'!$A$1:$I$222,4,FALSE) -> VP Financeiro e Relações Investidores | E8: Planejamento e Controle Integrado | G8: Falta de visibilidade no planejamento de projetos | H8: Ausência de Relacionamentos
A9: 15 | B9: =VLOOKUP($A9,' Lista de Entrevistas'!$A$1:$I$222,5,FALSE) -> Corporativo | C9: =VLOOKUP($A9,' Lista de Entrevistas'!$A$1:$I$222,4,FALSE) -> VP Financeiro e Relações Investidores | E9: Tecnologia, Dados e Sistemas | G9: Confiabilidade das informações recebidas | H9: Falta de Confiabilidade
A10: 15 | B10: =VLOOKUP($A10,' Lista de Entrevistas'!$A$1:$I$222,5,FALSE) -> Corporativo | C10: =VLOOKUP($A10,' Lista de Entrevistas'!$A$1:$I$222,4,FALSE) -> VP Financeiro e Relações Investidores | E10: Organização, Cultura e Modelo Operacional | G10: Falta de clareza de papéis e responsabilidades do núcleo de CapEx | H10: Ineficiência por ausência de responsabilidade
A11: 15 | B11: =VLOOKUP($A11,' Lista de Entrevistas'!$A$1:$I$222,5,FALSE) -> Corporativo | C11: =VLOOKUP($A11,' Lista de Entrevistas'!$A$1:$I$222,4,FALSE) -> VP Financeiro e Relações Investidores | E11: Organização, Cultura e Modelo Operacional | G11: Elevada quantidade de iniciativas de transformação | H11: Sobrecarga de recursos
A12: 16 | B12: =VLOOKUP($A12,' Lista de Entrevistas'!$A$1:$I$222,5,FALSE) -> Trilhos | C12: =VLOOKUP($A12,' Lista de Entrevistas'!$A$1:$I$222,4,FALSE) -> VP Trilhos | E12: Organização, Cultura e Modelo Operacional | F12: Suprimentos e financeiro são áreas de apoio, mas não vivem o dia a dia do negócio, o que gera desalinhamento de prioridades e senso de urgência. | G12: Interfaces fracas entre áreas e suportes | H12: Produtividade e retrabalho | I12: Organizacional | J12: Sim
A13: 16 | B13: =VLOOKUP($A13,' Lista de Entrevistas'!$A$1:$I$222,5,FALSE) -> Trilhos | C13: =VLOOKUP($A13,' Lista de Entrevistas'!$A$1:$I$222,4,FALSE) -> VP Trilhos | E13: Organização, Cultura e Modelo Operacional | F13: Suprimentos e financeiro são áreas de apoio, mas não vivem o dia a dia do negócio, o que gera desalinhamento de prioridades e senso de urgência. | G13: Interfaces fracas entre áreas e suportes | H13: Previsibilidade de prazo e marcos | I13: Organizacional | J13: Sim
A14: 16 | B14: =VLOOKUP($A14,' Lista de Entrevistas'!$A$1:$I$222,5,FALSE) -> Trilhos | C14: =VLOOKUP($A14,' Lista de Entrevistas'!$A$1:$I$222,4,FALSE) -> VP Trilhos | E14: Organização, Cultura e Modelo Operacional | F14: Suprimentos atende sob demanda, sem atuação preventiva ou imersão no negócio. | G14: Atuação reativa de áreas de apoio | H14: Previsibilidade de prazo e marcos | I14: Organizacional | J14: Sim
A15: 16 | B15: =VLOOKUP($A15,' Lista de Entrevistas'!$A$1:$I$222,5,FALSE) -> Trilhos | C15: =VLOOKUP($A15,' Lista de Entrevistas'!$A$1:$I$222,4,FALSE) -> VP Trilhos | E15: Organização, Cultura e Modelo Operacional | F15: Suprimentos atende sob demanda, sem atuação preventiva ou imersão no negócio. | G15: Atuação reativa de áreas de apoio | H15: Produtividade e retrabalho | I15: Organizacional | J15: Sim
A16: 16 | B16: =VLOOKUP($A16,' Lista de Entrevistas'!$A$1:$I$222,5,FALSE) -> Trilhos | C16: =VLOOKUP($A16,' Lista de Entrevistas'!$A$1:$I$222,4,FALSE) -> VP Trilhos | E16: Tecnologia, Dados e Sistemas | F16: Consolidação de dados de CAPEX depende de múltiplos sistemas e reconciliações manuais. | G16: Sistemas fragmentados e consolidação manual | H16: Dados, transparência e rastreabilidade | I16: Sistêmico | J16: Sim
A17: 16 | B17: =VLOOKUP($A17,' Lista de Entrevistas'!$A$1:$I$222,5,FALSE) -> Trilhos | C17: =VLOOKUP($A17,' Lista de Entrevistas'!$A$1:$I$222,4,FALSE) -> VP Trilhos | E17: Tecnologia, Dados e Sistemas | F17: Consolidação de dados de CAPEX depende de múltiplos sistemas e reconciliações manuais. | G17: Sistemas fragmentados e consolidação manual | H17: Produtividade e retrabalho | I17: Sistêmico | J17: Sim
A18: 16 | B18: =VLOOKUP($A18,' Lista de Entrevistas'!$A$1:$I$222,5,FALSE) -> Trilhos | C18: =VLOOKUP($A18,' Lista de Entrevistas'!$A$1:$I$222,4,FALSE) -> VP Trilhos | E18: Organização, Cultura e Modelo Operacional | F18: Integração centralizada busca garantir uniformidade, mas há risco de cada vertical operar de forma distinta. | G18: Baixa padronização entre unidades/verticais | H18: Produtividade e retrabalho | I18: Organizacional | J18: Sim
A19: 16 | B19: =VLOOKUP($A19,' Lista de Entrevistas'!$A$1:$I$222,5,FALSE) -> Trilhos | C19: =VLOOKUP($A19,' Lista de Entrevistas'!$A$1:$I$222,4,FALSE) -> VP Trilhos | E19: Organização, Cultura e Modelo Operacional | F19: Suprimentos e financeiro são áreas de apoio, mas não vivem o dia a dia do negócio, o que gera desalinhamento de prioridades e senso de urgência. | G19: Interfaces fracas entre áreas e suportes | H19: Produtividade e retrabalho | I19: Organizacional | J19: Sim
A20: 13 | B20: =VLOOKUP($A20,' Lista de Entrevistas'!$A$1:$I$222,5,FALSE) -> Trilhos | C20: =VLOOKUP($A20,' Lista de Entrevistas'!$A$1:$I$222,4,FALSE) -> VP Trilhos | E20: Organização, Cultura e Modelo Operacional | F20: Relato de conflitos e retrabalho sob modelo matricial anterior, com áreas especializadas atuando de forma pouco integrada. | G20: Integração matricial inefetiva entre áreas | H20: Produtividade e retrabalho | I20: Organizacional | J20: Não
A21: 13 | B21: =VLOOKUP($A21,' Lista de Entrevistas'!$A$1:$I$222,5,FALSE) -> Trilhos | C21: =VLOOKUP($A21,' Lista de Entrevistas'!$A$1:$I$222,4,FALSE) -> VP Trilhos | E21: Organização, Cultura e Modelo Operacional | F21: Relato de conflitos e retrabalho sob modelo matricial anterior, com áreas especializadas atuando de forma pouco integrada. | G21: Integração matricial inefetiva entre áreas | H21: Previsibilidade de prazo e marcos | I21: Organizacional | J21: Não
A22: 13 | B22: =VLOOKUP($A22,' Lista de Entrevistas'!$A$1:$I$222,5,FALSE) -> Trilhos | C22: =VLOOKUP($A22,' Lista de Entrevistas'!$A$1:$I$222,4,FALSE) -> VP Trilhos | E22: Governança Técnica e Engenharia | F22: Tentativa recente de estruturar processos preventivos, mas ainda com lacunas de integração entre áreas (ex: operação/manutenção). | G22: Integração CAPEX-OPEX e requisitos operacionais frágil | H22: Qualidade técnica, construtibilidade e mudanças tardias | I22: Organizacional | J22: Sim
A23: 13 | B23: =VLOOKUP($A23,' Lista de Entrevistas'!$A$1:$I$222,5,FALSE) -> Trilhos | C23: =VLOOKUP($A23,' Lista de Entrevistas'!$A$1:$I$222,4,FALSE) -> VP Trilhos | E23: Governança Técnica e Engenharia | F23: Tentativa recente de estruturar processos preventivos, mas ainda com lacunas de integração entre áreas (ex: operação/manutenção). | G23: Integração CAPEX-OPEX e requisitos operacionais frágil | H23: Previsibilidade de custo e acurácia de estimativas | I23: Organizacional | J23: Sim
... A28: 13 | B28: =VLOOKUP($A28,' Lista de Entrevistas'!$A$1:$I$222,5,FALSE) -> Trilhos | C28: =VLOOKUP($A28,' Lista de Entrevistas'!$A$1:$I$222,4,FALSE) -> VP Trilhos | E28: Organização, Cultura e Modelo Operacional | F28: Mudança para estrutura verticalizada visando autonomia e foco no resultado do empreendimento. | G28: Baixa padronização entre unidades/verticais | H28: Produtividade e retrabalho | I28: Organizacional | J28: Sim

Sheet Referências
A1: Disciplina | B1: Problema estrutural | C1: Descrição do Problema Estrutural | D1: Abrangência | E1: Impactos | F1: Recorrente | G1: Nº Relatórios | H1: Menção Literal (com autor) | I1: Relatórios
A2: Tecnologia, Dados e Sistemas | B2: Sistemas fragmentados e consolidação manual | C2: Múltiplos sistemas não integrados exigem consolidação manual recorrente para reporte e decisão. | D2: Sistêmico | E2: Dados; Produtividade | F2: Sim | G2: 8 | H2: “Múltiplos sistemas não conversam, exigindo tratamento manual.” – Adriana Martins dos Santos “Dependência de repasse de dados para consolidação.” – Rebeka Yang Wang | I2: ANDRE LUIS TEIXEIRA OLIVEIRA FREITAS; Adriana Martins dos Santos; Elmo Serejo Pithon Copello; Guilherme Tellis; Rebeka Yang Wang; Rodrigo Mitsuo Kise; Vanilza de Souza Pandolfo; WILLIAM NASCIMENTO MARINS
A3: Planejamento e Controle Integrado | B3: Controle integrado de prazos insuficiente | C3: Planejamento não estruturado por restrições e baixa integração entre cronograma, execução e controle. | D3: Multi-Projeto | E3: Prazo; Dados | F3: Sim | G3: 5 | H3: “Problemas só são revelados na execução.” – Michel Simoes Araujo “Cumprimento de prazos não é previsível.” – Guilherme Tellis | I3: Guilherme Tellis; Jean Carlos Bonin da Silva; Michel Simoes Araujo; Rodrigo Mitsuo Kise; WILLIAM NASCIMENTO MARINS
A4: Governança Técnica e Engenharia | B4: Integração CAPEX-OPEX e requisitos operacionais frágil | C4: Decisões de investimento não incorporam formalmente critérios operacionais e impacto futuro de OPEX. | D4: Organizacional | E4: Custo; Produtividade; Qualidade Técnica | F4: Sim | G4: 4 | H4: “Trade-off entre CAPEX e OPEX não é estruturado.” – Ricardo Alexandre Pereira Benicio “Operação participa sem critérios formais.” – Elmo Serejo Pithon Copello | I4: ANDRE LUIS TEIXEIRA OLIVEIRA FREITAS; Elmo Serejo Pithon Copello; Ricardo Alexandre Pereira Benicio; Rodrigo Correa de Souza
A5: Organização, Cultura e Modelo Operacional | B5: Interfaces fracas entre áreas e suportes | C5: Falta alinhamento estruturado entre áreas técnicas, operacionais e corporativas, gerando conflito e retrabalho. | D5: Organizacional | E5: Produtividade; Prazo | F5: Sim | G5: 4 | H5: “Conflitos entre diretores impactam projetos.” – Guilherme Tellis “Falhas de comunicação entre áreas.” – Rodrigo Correa de Souza | I5: Adriana Martins dos Santos; Guilherme Tellis; Rebeka Yang Wang; Rodrigo Correa de Souza
A6: Organização, Cultura e Modelo Operacional | B6: Papéis e responsabilidades não definidos | C6: Ausência de delimitação clara de responsabilidades ponta-a-ponta e accountability transversal. | D6: Organizacional | E6: Produtividade; Riscos; Dados | F6: Sim | G6: 3 | H6: “Escopo se mistura.” – Adriana Martins dos Santos “Sem consolidação ou visão integrada.” – Rebeka Yang Wang | I6: Adriana Martins dos Santos; Rebeka Yang Wang; Rodrigo Correa de Souza
A7: Gestão Contratual e Riscos | B7: Governança de riscos e contingências insuficiente | C7: Gestão de riscos não plenamente integrada ao planejamento, orçamento e decisões executivas. | D7: Organizacional | E7: Riscos; Custo; Prazo | F7: Sim | G7: 3 | H7: “Cultura de riscos concentrada na área central.” – Rodrigo Mitsuo Kise “Dependem de validação central.” – WILLIAM NASCIMENTO MARINS | I7: Guilherme Tellis; Rodrigo Mitsuo Kise; WILLIAM NASCIMENTO MARINS
A8: Suprimentos e Estratégia de Contratação | B8: Demanda chega imatura, compras reativas | C8: Projetos chegam à área de compras com baixa maturidade técnica, exigindo atuação emergencial. | D8: Multi-Projeto | E8: Prazo; Contratual; Produtividade | F8: Sim | G8: 2 | H8: “Apagar incêndios.” – Jean Carlos Bonin da Silva “Pouco tempo para negociação.” – Elmo Serejo Pithon Copello | I8: Elmo Serejo Pithon Copello; Jean Carlos Bonin da Silva
A9: Governança e Gestão de Portfólio | B9: Governança de decisão e priorização insuficiente | C9: Processo de priorização de investimentos não institucionalizado com critérios técnicos estruturados. | D9: Organizacional | E9: Portfólio; Prazo; Custo | F9: Sim | G9: 2 | H9: “Cada área defende seu próprio interesse.” – Rodrigo Correa de Souza “Sem filtro técnico.” – Adriana Martins dos Santos | I9: Adriana Martins dos Santos; Rodrigo Correa de Souza

Sheet Nuvem
A1: 1 | B1: Sistemas fragmentados e consolidação manual | C1: Sistemas"Fragmentados"
A2: =A1+1 -> 2 | B2: Sistemas fragmentados e consolidação manual | C2: Sistemas"Fragmentados"
A3: =A2+1 -> 3 | B3: Sistemas fragmentados e consolidação manual | C3: Sistemas"Fragmentados"
A4: =A3+1 -> 4 | B4: Sistemas fragmentados e consolidação manual | C4: Sistemas"Fragmentados"
A5: =A4+1 -> 5 | B5: Sistemas fragmentados e consolidação manual | C5: Sistemas"Fragmentados"
A6: =A5+1 -> 6 | B6: Sistemas fragmentados e consolidação manual | C6: Sistemas"Fragmentados"
A7: =A6+1 -> 7 | B7: Sistemas fragmentados e consolidação manual | C7: Sistemas"Fragmentados"
A8: =A7+1 -> 8 | B8: Sistemas fragmentados e consolidação manual | C8: Sistemas"Fragmentados"
A9: 1 | B9: Controle integrado de prazos insuficiente | C9: Controle"Prazos"Insuficientes
A10: 2 | B10: Controle integrado de prazos insuficiente | C10: Controle"Prazos"Insuficientes
A11: 3 | B11: Controle integrado de prazos insuficiente | C11: Controle"Prazos"Insuficientes
A12: 4 | B12: Controle integrado de prazos insuficiente | C12: Controle"Prazos"Insuficientes
A13: 5 | B13: Controle integrado de prazos insuficiente | C13: Controle"Prazos"Insuficientes
A14: 1 | B14: Integração CAPEX-OPEX e requisitos operacionais frágil | C14: Integração"CapexOpex"
A15: 2 | B15: Integração CAPEX-OPEX e requisitos operacionais frágil | C15: Integração"CapexOpex"
A16: 3 | B16: Integração CAPEX-OPEX e requisitos operacionais frágil | C16: Integração"CapexOpex"
A17: 4 | B17: Integração CAPEX-OPEX e requisitos operacionais frágil | C17: Integração"CapexOpex"
A18: 1 | B18: Interfaces fracas entre áreas e suportes | C18: Interfaces/Áreas
A19: 2 | B19: Interfaces fracas entre áreas e suportes | C19: Interfaces/Áreas
A20: 3 | B20: Interfaces fracas entre áreas e suportes | C20: Interfaces/Áreas
... A27: 3 | B27: Papéis e responsabilidades não definidos | C27: Papeis&Responsabilidades
A28: 1 | B28: Governança de decisão e priorização insuficiente
A29: 2 | B29: Governança de decisão e priorização insuficiente
A30: 1 | B30: Trade-off CAPEX/OPEX sem governança | C30: Governça;Capex/Opex
A31: 2 | B31: Trade-off CAPEX/OPEX sem governança
A32: 1 | B32: Atuação reativa de áreas de apoio
A33: 2 | B33: Atuação reativa de áreas de apoio
A34: 1 | B34: Baixa padronização entre unidades/verticais | C34: Despadronização
A35: 2 | B35: Baixa padronização entre unidades/verticais
A36: 1 | B36: Sequenciamento físico subordinado ao econômico-financeiro
A37: 2 | B37: Sequenciamento físico subordinado ao econômico-financeiro
A38: 1 | B38: Rastreabilidade insuficiente de informações | C38: Rastreabilidade
A39: 2 | B39: Rastreabilidade insuficiente de informações

Sheet Tensões_Estruturais
A1: tema | B1: área_A | C1: área_B | D1: conflito | E1: evidência | F1: tipo de tensão

Sheet Planilha1
A1: entrevista_id | B1: Plataforma | C1: Diretoria | D1: Gerência Executiva | E1: Disciplina | F1: Evidência literal | G1: Problema estrutural | H1: Impacto | I1: Abrangência | J1: Recorrente
A2: Adriana Martins dos Santos | B2: Trilhos | C2: Engenharia e Implantação | D2: Não informado | E2: Organização, Cultura e Modelo Operacional | F2: Suprimentos e financeiro são áreas de apoio, mas não vivem o dia a dia do negócio, o que gera desalinhamento de prioridades e senso de urgência. | G2: Interfaces fracas entre áreas e suportes | H2: Produtividade e retrabalho | I2: Organizacional | J2: Sim
A3: Adriana Martins dos Santos | B3: Trilhos | C3: Engenharia e Implantação | D3: Não informado | E3: Organização, Cultura e Modelo Operacional | F3: Suprimentos e financeiro são áreas de apoio, mas não vivem o dia a dia do negócio, o que gera desalinhamento de prioridades e senso de urgência. | G3: Interfaces fracas entre áreas e suportes | H3: Previsibilidade de prazo e marcos | I3: Organizacional | J3: Sim
A4: Adriana Martins dos Santos | B4: Trilhos | C4: Engenharia e Implantação | D4: Não informado | E4: Organização, Cultura e Modelo Operacional | F4: Suprimentos atende sob demanda, sem atuação preventiva ou imersão no negócio. | G4: Atuação reativa de áreas de apoio | H4: Previsibilidade de prazo e marcos | I4: Organizacional | J4: Sim
A5: Adriana Martins dos Santos | B5: Trilhos | C5: Engenharia e Implantação | D5: Não informado | E5: Organização, Cultura e Modelo Operacional | F5: Suprimentos atende sob demanda, sem atuação preventiva ou imersão no negócio. | G5: Atuação reativa de áreas de apoio | H5: Produtividade e retrabalho | I5: Organizacional | J5: Sim
A6: Adriana Martins dos Santos | B6: Trilhos | C6: Engenharia e Implantação | D6: Não informado | E6: Tecnologia, Dados e Sistemas | F6: Consolidação de dados de CAPEX depende de múltiplos sistemas e reconciliações manuais. | G6: Sistemas fragmentados e consolidação manual | H6: Dados, transparência e rastreabilidade | I6: Sistêmico | J6: Sim
A7: Adriana Martins dos Santos | B7: Trilhos | C7: Engenharia e Implantação | D7: Não informado | E7: Tecnologia, Dados e Sistemas | F7: Consolidação de dados de CAPEX depende de múltiplos sistemas e reconciliações manuais. | G7: Sistemas fragmentados e consolidação manual | H7: Produtividade e retrabalho | I7: Sistêmico | J7: Sim
A8: Adriana Martins dos Santos | B8: Trilhos | C8: Engenharia e Implantação | D8: Não informado | E8: Organização, Cultura e Modelo Operacional | F8: Integração centralizada busca garantir uniformidade, mas há risco de cada vertical operar de forma distinta. | G8: Baixa padronização entre unidades/verticais | H8: Produtividade e retrabalho | I8: Organizacional | J8: Sim
A9: Adriana Martins dos Santos | B9: Trilhos | C9: Engenharia e Implantação | D9: Não informado | E9: Organização, Cultura e Modelo Operacional | F9: Suprimentos e financeiro são áreas de apoio, mas não vivem o dia a dia do negócio, o que gera desalinhamento de prioridades e senso de urgência. | G9: Interfaces fracas entre áreas e suportes | H9: Produtividade e retrabalho | I9: Organizacional | J9: Sim
A10: ANDRE LUIS TEIXEIRA OLIVEIRA FREITAS | B10: Trilhos | C10: Engenharia e Implantação | D10: Não informado | E10: Organização, Cultura e Modelo Operacional | F10: Relato de conflitos e retrabalho sob modelo matricial anterior, com áreas especializadas atuando de forma pouco integrada. | G10: Integração matricial inefetiva entre áreas | H10: Produtividade e retrabalho | I10: Organizacional | J10: Não
A11: ANDRE LUIS TEIXEIRA OLIVEIRA FREITAS | B11: Trilhos | C11: Engenharia e Implantação | D11: Não informado | E11: Organização, Cultura e Modelo Operacional | F11: Relato de conflitos e retrabalho sob modelo matricial anterior, com áreas especializadas atuando de forma pouco integrada. | G11: Integração matricial inefetiva entre áreas | H11: Previsibilidade de prazo e marcos | I11: Organizacional | J11: Não
A12: ANDRE LUIS TEIXEIRA OLIVEIRA FREITAS | B12: Trilhos | C12: Engenharia e Implantação | D12: Não informado | E12: Governança Técnica e Engenharia | F12: Tentativa recente de estruturar processos preventivos, mas ainda com lacunas de integração entre áreas (ex: operação/manutenção). | G12: Integração CAPEX-OPEX e requisitos operacionais frágil | H12: Qualidade técnica, construtibilidade e mudanças tardias | I12: Organizacional | J12: Sim
... A43: Elmo Serejo Pithon Copello | B43: Trilhos | C43: Não informado | D43: Não informado | E43: Governança Técnica e Engenharia | F43: Tentativa recente de estruturar processos preventivos, mas ainda com lacunas de integração entre áreas (ex: operação/manutenção). | G43: Integração CAPEX-OPEX e requisitos operacionais frágil | H43: Produtividade e retrabalho | I43: Organizacional | J43: Sim

Sheet Analise Individual (2)
A1: entrevista_id | B1: entrevistado | C1: nivel | D1: plataforma | E1: evidencia | F1: problema_estrutural | G1: disciplina | H1: dimensao | I1: impacto | J1: abrangencia | K1: recorrente
A2: =_xlfn.XLOOKUP(B2,' Lista de Entrevistas'!B:B,' Lista de Entrevistas'!A:A,"") -> 1 | B2: Paulo Cesar Martins Amaral | C2: Gerência | D2: Trilhos | E2: A administração contratual está sendo estruturada com a bicicleta andando. | F2: Gestão contratual e riscos pulverizada entre áreas | G2: Modelo organizacional | H2: Estrutura Organizacional e Governança do CAPEX | I2: Performance Contratual e Cadeia de Fornecimento | J2: Organizacional | K2: Sim
A3: =_xlfn.XLOOKUP(B3,' Lista de Entrevistas'!B:B,' Lista de Entrevistas'!A:A,"") -> 1 | B3: Paulo Cesar Martins Amaral | C3: Gerência | D3: Trilhos | E3: A administração contratual está sendo estruturada com a bicicleta andando. | F3: Gestão contratual e riscos pulverizada entre áreas | G3: Modelo organizacional | H3: Estrutura Organizacional e Governança do CAPEX | I3: Efetividade da Governança de CAPEX | J3: Organizacional | K3: Sim
A4: =_xlfn.XLOOKUP(B4,' Lista de Entrevistas'!B:B,' Lista de Entrevistas'!A:A,"") -> 1 | B4: Paulo Cesar Martins Amaral | C4: Gerência | D4: Trilhos | E4: Foi necessário difundir cultura de administração contratual e de registro. | F4: Comunicação contratual sem padronização nem controle | G4: Administração contratual | H4: Gestão Contratual e Contingências | I4: Performance Contratual e Cadeia de Fornecimento | J4: Organizacional | K4: Sim
A5: =_xlfn.XLOOKUP(B5,' Lista de Entrevistas'!B:B,' Lista de Entrevistas'!A:A,"") -> 1 | B5: Paulo Cesar Martins Amaral | C5: Gerência | D5: Trilhos | E5: Foi necessário difundir cultura de administração contratual e de registro. | F5: Comunicação contratual sem padronização nem controle | G5: Administração contratual | H5: Gestão Contratual e Contingências | I5: Confiabilidade da Informação e Suporte à Decisão | J5: Organizacional | K5: Sim
A6: =_xlfn.XLOOKUP(B6,' Lista de Entrevistas'!B:B,' Lista de Entrevistas'!A:A,"") -> 1 | B6: Paulo Cesar Martins Amaral | C6: Gerência | D6: Trilhos | E6: Projetos básicos ou sem projeto viraram oportunidades para muitos pleitos. | F6: Termos de referência rasos geram retrabalho contratual | G6: Padrões e templates | H6: Metodologias e Engenharia de Valor | I6: Performance Contratual e Cadeia de Fornecimento | J6: Organizacional | K6: Sim
A7: =_xlfn.XLOOKUP(B7,' Lista de Entrevistas'!B:B,' Lista de Entrevistas'!A:A,"") -> 1 | B7: Paulo Cesar Martins Amaral | C7: Gerência | D7: Trilhos | E7: Projetos básicos ou sem projeto viraram oportunidades para muitos pleitos. | F7: Termos de referência rasos geram retrabalho contratual | G7: Padrões e templates | H7: Metodologias e Engenharia de Valor | I7: Eficiência e Controle de Capital | J7: Organizacional | K7: Sim
A8: =_xlfn.XLOOKUP(B8,' Lista de Entrevistas'!B:B,' Lista de Entrevistas'!A:A,"") -> 2 | B8: Paulo Henrique de Almeida Aredes | C8: Gerência | D8: Trilhos | E8: Governança e burocracias travam o processo de medição e pagamento. | F8: Processos operacionais de pagamento geram atraso aos fornecedores | G8: Administração contratual | H8: Gestão Contratual e Contingências | I8: Performance Contratual e Cadeia de Fornecimento | J8: Organizacional | K8: Sim
A9: =_xlfn.XLOOKUP(B9,' Lista de Entrevistas'!B:B,' Lista de Entrevistas'!A:A,"") -> 2 | B9: Paulo Henrique de Almeida Aredes | C9: Gerência | D9: Trilhos | E9: Governança e burocracias travam o processo de medição e pagamento. | F9: Processos operacionais de pagamento geram atraso aos fornecedores | G9: Administração contratual | H9: Gestão Contratual e Contingências | I9: Previsibilidade de Prazo e Entrega | J9: Organizacional | K9: Sim
A10: =_xlfn.XLOOKUP(B10,' Lista de Entrevistas'!B:B,' Lista de Entrevistas'!A:A,"") -> 2 | B10: Paulo Henrique de Almeida Aredes | C10: Gerência | D10: Trilhos | E10: Quanto mais demora para pagar, mais o fornecedor pequeno é prejudicado. | F10: Fornecedores pequenos não suportam prazos de governança | G10: Exposição financeira | H10: Gestão Contratual e Contingências | I10: Performance Contratual e Cadeia de Fornecimento | J10: Multi-Projeto | K10: Sim
A11: =_xlfn.XLOOKUP(B11,' Lista de Entrevistas'!B:B,' Lista de Entrevistas'!A:A,"") -> 2 | B11: Paulo Henrique de Almeida Aredes | C11: Gerência | D11: Trilhos | E11: Quanto mais demora para pagar, mais o fornecedor pequeno é prejudicado. | F11: Fornecedores pequenos não suportam prazos de governança | G11: Exposição financeira | H11: Gestão Contratual e Contingências | I11: Exposição a Riscos de Investimento | J11: Multi-Projeto | K11: Sim
A12: =_xlfn.XLOOKUP(B12,' Lista de Entrevistas'!B:B,' Lista de Entrevistas'!A:A,"") -> 2 | B12: Paulo Henrique de Almeida Aredes | C12: Gerência | D12: Trilhos | E12: Mesmo com mérito, um pleito pode não ser aceito pelo concedente. | F12: Estratégia de contratação condicionada pelo poder concedente | G12: Integração com áreas corporativas | H12: Gestão Contratual e Contingências | I12: Exposição a Riscos de Investimento | J12: Multi-Projeto | K12: Não
A13: =_xlfn.XLOOKUP(B13,' Lista de Entrevistas'!B:B,' Lista de Entrevistas'!A:A,"") -> 2 | B13: Paulo Henrique de Almeida Aredes | C13: Gerência | D13: Trilhos | E13: Mesmo com mérito, um pleito pode não ser aceito pelo concedente. | F13: Estratégia de contratação condicionada pelo poder concedente | G13: Integração com áreas corporativas | H13: Gestão Contratual e Contingências | I13: Performance Contratual e Cadeia de Fornecimento | J13: Multi-Projeto | K13: Não
... A366: =_xlfn.XLOOKUP(B366,' Lista de Entrevistas'!B:B,' Lista de Entrevistas'!A:A,"") -> 53 | B366: Gabriel Bittencourt Jacondino | C366: Gerência Executiva | D366: Trilhos | E366: “Isso te leva a um sobrecusto que eu não vou conseguir cobrar.” | F366: Escopo excedente gera sobrecusto não recuperável | G366: Exposição financeira | H366: Gestão Contratual e Contingências | I366: Eficiência e Controle de Capital | J366: Multi-Projeto | K366: Sim
A367: =_xlfn.XLOOKUP(B367,' Lista de Entrevistas'!B:B,' Lista de Entrevistas'!A:A,"") -> 54 | B367: Alexandro Marcelo Zopolato Francisco
A368: =_xlfn.XLOOKUP(B368,' Lista de Entrevistas'!B:B,' Lista de Entrevistas'!A:A,"") -> 54 | B368: Alexandro Marcelo Zopolato Francisco | C368: Gerência Executiva | D368: Rodovias | E368: “Eu cuido de todos os investimentos… tenho que explicar custo e prazo.” | F368: Alta dependência de gestão individualizada | G368: Papéis e responsabilidades | H368: Estrutura Organizacional e Governança do CAPEX | I368: Eficiência Operacional da Execução | J368: Organizacional | K368: Sim
A369: =_xlfn.XLOOKUP(B369,' Lista de Entrevistas'!B:B,' Lista de Entrevistas'!A:A,"") -> 54 | B369: Alexandro Marcelo Zopolato Francisco | C369: Gerência Executiva | D369: Rodovias | E369: “Eu geralmente vou sozinho… é muita informação em pouco tempo.” | F369: Capacidade insuficiente para demandas estratégicas | G369: Capacidade e competências | H369: Estrutura Organizacional e Governança do CAPEX | I369: Qualidade da Tomada de Decisão de Investimentos | J369: Organizacional | K369: Sim
A370: =_xlfn.XLOOKUP(B370,' Lista de Entrevistas'!B:B,' Lista de Entrevistas'!A:A,"") -> 54 | B370: Alexandro Marcelo Zopolato Francisco | C370: Gerência Executiva | D370: Rodovias | E370: “A interface é com todos… não tem como fazer nada sozinho.” | F370: Alto grau de dependência de interfaces | G370: Integração com áreas corporativas | H370: Estrutura Organizacional e Governança do CAPEX | I370: Eficiência Operacional da Execução | J370: Organizacional | K370: Sim
A371: =_xlfn.XLOOKUP(B371,' Lista de Entrevistas'!B:B,' Lista de Entrevistas'!A:A,"") -> 54 | B371: Alexandro Marcelo Zopolato Francisco | C371: Gerência Executiva | D371: Rodovias | E371: “Eu não converso com todo mundo… falo com a integradora.” | F371: Dependência de intermediários na gestão | G371: Modelo organizacional | H371: Estrutura Organizacional e Governança do CAPEX | I371: Efetividade da Governança de CAPEX | J371: Organizacional | K371: Sim
